Traceback (most recent call last):
  File "/Users/gabriel/.virtualenv/imnum/lib/python3.9/site-packages/jupyter_cache/executors/utils.py", line 51, in single_nb_execution
    executenb(
  File "/Users/gabriel/.virtualenv/imnum/lib/python3.9/site-packages/nbclient/client.py", line 1204, in execute
    return NotebookClient(nb=nb, resources=resources, km=km, **kwargs).execute()
  File "/Users/gabriel/.virtualenv/imnum/lib/python3.9/site-packages/nbclient/util.py", line 84, in wrapped
    return just_run(coro(*args, **kwargs))
  File "/Users/gabriel/.virtualenv/imnum/lib/python3.9/site-packages/nbclient/util.py", line 62, in just_run
    return loop.run_until_complete(coro)
  File "/usr/local/Cellar/python@3.9/3.9.14/Frameworks/Python.framework/Versions/3.9/lib/python3.9/asyncio/base_events.py", line 647, in run_until_complete
    return future.result()
  File "/Users/gabriel/.virtualenv/imnum/lib/python3.9/site-packages/nbclient/client.py", line 663, in async_execute
    await self.async_execute_cell(
  File "/Users/gabriel/.virtualenv/imnum/lib/python3.9/site-packages/nbclient/client.py", line 965, in async_execute_cell
    await self._check_raise_for_error(cell, cell_index, exec_reply)
  File "/Users/gabriel/.virtualenv/imnum/lib/python3.9/site-packages/nbclient/client.py", line 862, in _check_raise_for_error
    raise CellExecutionError.from_cell_and_msg(cell, exec_reply_content)
nbclient.exceptions.CellExecutionError: An error occurred while executing the following cell:
------------------
# modules
from imports import np, plt, iio, cv2, gaussian, Path, gf, filters, data, fusion, recalage

# functions
from imports import gray_to_rgb, plot_images

# variables
from imports import BASE_DIR, multi_exposure_dataset, multi_focus_dataset, ours_dataset, multi_exposure_sample, multi_exposure_sample, multi_focus_sample, ours_sample, gray_sample
------------------

[0;31m---------------------------------------------------------------------------[0m
[0;31mModuleNotFoundError[0m                       Traceback (most recent call last)
Cell [0;32mIn [1], line 2[0m
[1;32m      1[0m [38;5;66;03m# modules[39;00m
[0;32m----> 2[0m [38;5;28;01mfrom[39;00m [38;5;21;01mimports[39;00m [38;5;28;01mimport[39;00m np, plt, iio, cv2, gaussian, Path, gf, filters, data, fusion, recalage
[1;32m      4[0m [38;5;66;03m# functions[39;00m
[1;32m      5[0m [38;5;28;01mfrom[39;00m [38;5;21;01mimports[39;00m [38;5;28;01mimport[39;00m gray_to_rgb, plot_images

File [0;32m~/Documents/Ulm/M2/MVA/S1/ImNum/projet/docs/imports.py:9[0m
[1;32m      6[0m [38;5;28;01mfrom[39;00m [38;5;21;01mpathlib[39;00m [38;5;28;01mimport[39;00m Path
[1;32m      8[0m [38;5;66;03m# Our own implementation[39;00m
[0;32m----> 9[0m [38;5;28;01mimport[39;00m [38;5;21;01mgf[39;00m
[1;32m     10[0m [38;5;28;01mimport[39;00m [38;5;21;01mgf[39;00m[38;5;21;01m.[39;00m[38;5;21;01mfilters[39;00m [38;5;28;01mas[39;00m [38;5;21;01mfilters[39;00m
[1;32m     11[0m [38;5;28;01mimport[39;00m [38;5;21;01mgf[39;00m[38;5;21;01m.[39;00m[38;5;21;01mdata[39;00m [38;5;28;01mas[39;00m [38;5;21;01mdata[39;00m

[0;31mModuleNotFoundError[0m: No module named 'gf'
ModuleNotFoundError: No module named 'gf'

